[0m18:33:07.323035 [debug] [MainThread]: Sending event: {'category': 'dbt', 'action': 'invocation', 'label': 'start', 'context': [<snowplow_tracker.self_describing_json.SelfDescribingJson object at 0x7f377d3c89a0>, <snowplow_tracker.self_describing_json.SelfDescribingJson object at 0x7f377daaf940>, <snowplow_tracker.self_describing_json.SelfDescribingJson object at 0x7f377daaf910>]}


============================== 18:33:07.340504 | 5b904a28-f403-42ba-9122-09f00065655b ==============================
[0m18:33:07.340504 [info ] [MainThread]: Running with dbt=1.7.7
[0m18:33:07.345098 [debug] [MainThread]: running dbt with arguments {'printer_width': '80', 'indirect_selection': 'eager', 'log_cache_events': 'False', 'write_json': 'True', 'partial_parse': 'True', 'cache_selected_only': 'False', 'profiles_dir': '/home/eogwal/.dbt', 'version_check': 'True', 'debug': 'False', 'log_path': 'logs', 'fail_fast': 'False', 'warn_error': 'None', 'use_colors': 'True', 'use_experimental_parser': 'False', 'no_print': 'None', 'quiet': 'False', 'log_format': 'default', 'invocation_command': 'dbt init', 'introspect': 'True', 'static_parser': 'True', 'target_path': 'None', 'warn_error_options': 'WarnErrorOptions(include=[], exclude=[])', 'send_anonymous_usage_stats': 'True'}
[0m18:33:07.350349 [warn ] [MainThread]: [ConfigFolderDirectory]: Unable to parse dict {'dir': PosixPath('/home/eogwal/.dbt')}
[0m18:33:07.353879 [info ] [MainThread]: Creating dbt configuration folder at 
[0m18:33:16.020346 [debug] [MainThread]: Starter project path: /home/eogwal/Desktop/de_airbyte/elt/dbt-env/lib/python3.8/site-packages/dbt/include/starter_project
[0m18:33:16.033229 [info ] [MainThread]: 
Your new dbt project "custom_postgres" was created!

For more information on how to configure the profiles.yml file,
please consult the dbt documentation here:

  https://docs.getdbt.com/docs/configure-your-profile

One more thing:

Need help? Don't hesitate to reach out to us via GitHub issues or on Slack:

  https://community.getdbt.com/

Happy modeling!

[0m18:33:16.035269 [info ] [MainThread]: Setting up your profile.
[0m18:35:06.253191 [error] [MainThread]: Encountered an error:

[0m18:35:06.262727 [error] [MainThread]: Traceback (most recent call last):
  File "/home/eogwal/Desktop/de_airbyte/elt/dbt-env/lib/python3.8/site-packages/dbt/cli/requires.py", line 91, in wrapper
    result, success = func(*args, **kwargs)
  File "/home/eogwal/Desktop/de_airbyte/elt/dbt-env/lib/python3.8/site-packages/dbt/cli/requires.py", line 76, in wrapper
    return func(*args, **kwargs)
  File "/home/eogwal/Desktop/de_airbyte/elt/dbt-env/lib/python3.8/site-packages/dbt/cli/main.py", line 515, in init
    results = task.run()
  File "/home/eogwal/Desktop/de_airbyte/elt/dbt-env/lib/python3.8/site-packages/dbt/task/init.py", line 344, in run
    self.setup_profile(profile_name)
  File "/home/eogwal/Desktop/de_airbyte/elt/dbt-env/lib/python3.8/site-packages/dbt/task/init.py", line 264, in setup_profile
    self.create_profile_from_target(adapter, profile_name=profile_name)
  File "/home/eogwal/Desktop/de_airbyte/elt/dbt-env/lib/python3.8/site-packages/dbt/task/init.py", line 181, in create_profile_from_target
    self.create_profile_from_profile_template(profile_template, profile_name)
  File "/home/eogwal/Desktop/de_airbyte/elt/dbt-env/lib/python3.8/site-packages/dbt/task/init.py", line 165, in create_profile_from_profile_template
    target = self.generate_target_from_input(prompts, initial_target)
  File "/home/eogwal/Desktop/de_airbyte/elt/dbt-env/lib/python3.8/site-packages/dbt/task/init.py", line 131, in generate_target_from_input
    target[key] = click.prompt(
  File "/home/eogwal/Desktop/de_airbyte/elt/dbt-env/lib/python3.8/site-packages/click/termui.py", line 164, in prompt
    value = prompt_func(prompt)
  File "/home/eogwal/Desktop/de_airbyte/elt/dbt-env/lib/python3.8/site-packages/click/termui.py", line 147, in prompt_func
    raise Abort() from None
click.exceptions.Abort

[0m18:35:06.311215 [debug] [MainThread]: Resource report: {"command_name": "init", "command_wall_clock_time": 119.04913, "process_user_time": 7.17982, "process_kernel_time": 0.282889, "process_mem_max_rss": "89096", "process_in_blocks": "3752", "process_out_blocks": "80", "command_success": false}
[0m18:35:06.323361 [debug] [MainThread]: Command `dbt init` failed at 18:35:06.322123 after 119.06 seconds
[0m18:35:06.332915 [debug] [MainThread]: Sending event: {'category': 'dbt', 'action': 'invocation', 'label': 'end', 'context': [<snowplow_tracker.self_describing_json.SelfDescribingJson object at 0x7f377d3c89a0>, <snowplow_tracker.self_describing_json.SelfDescribingJson object at 0x7f377a177670>, <snowplow_tracker.self_describing_json.SelfDescribingJson object at 0x7f377a177d60>]}
[0m18:35:06.353753 [debug] [MainThread]: Flushing usage events
